Workbook

Sheet Population change 2018 to 2024
A1: Municipality | B1: Population between 20 and 64 in 2018 | C1: Population between 20 and 64 in 2024 | D1: Population between 20 and 64 change from 2018 to 2024
A2: Bever | B2: 411 | C2: 422 | D2: =C2/B2 -> 1.026764
A3: Bregaglia | B3: 895 | C3: 852 | D3: =C3/B3 -> 0.95195531
A4: Celerina/Schlarigna | B4: 1041 | C4: 949 | D4: =C4/B4 -> 0.91162344
A5: La Punt Chamues-ch | B5: 474 | C5: 457 | D5: =C5/B5 -> 0.96413502
A6: Madulain | B6: 125 | C6: 115 | D6: =C6/B6 -> 0.92
A7: Pontresina | B7: 1615 | C7: 1540 | D7: =C7/B7 -> 0.95356037
A8: S-chanf | B8: 416 | C8: 446 | D8: =C8/B8 -> 1.0721154
A9: Samedan | B9: 1924 | C9: 1920 | D9: =C9/B9 -> 0.997921
A10: Sils im Engadin/Segl | B10: 539 | C10: 514 | D10: =C10/B10 -> 0.95361781
A11: Silvaplana | B11: 771 | C11: 760 | D11: =C11/B11 -> 0.98573281
A12: St. Moritz | B12: 4488 | C12: 4832 | D12: =C12/B12 -> 1.0766488
A13: Zuoz | B13: 723 | C13: 691 | D13: =C13/B13 -> 0.95573997

Sheet Laborforce adjustment
A1: Home Municipality | B1: Work Municipality | C1: Number of people traveling between the home and work municipality for work in 2018 | D1: Number of people traveling between the home and work municipality for work in 2024 estimated based on population changes | E1: Assumed share of the population using public transportation for their work commute | F1: Assumed number of people using public transportation for their work commute | G1: Commute between municipalities in the study area | H1: Commute between the home municipality inside the study area and a destination to the east (to St. Moritz Sink) | I1: Total population going from their home municipality inside the study area to the St. Moritz Sink on their way to work by municipality | J1: Commute between a home municipality outside the study area and a destination in the study area (from St. Moritz Sink) | L1: Total population going to a municipality inside the study area from the the St. Moritz Sink on their way to work by municipality | M1: Work Municipality
A2: Vaz/Obervaz (home) | B2: St. Moritz (work) | C2: 6 | E2: 0.2 | F2: =C2*E2 -> 1.2 | J2: yes | L2: =(F2+F4+F9+F13+F14+F20+F24+F31+F41+F50+F58+F68+F78+F109+F139+F155+F158)/2 -> 124.67552 | M2: St. Moritz (work)
A3: Surses (home) | B3: Samedan (work) | C3: 5 | F3: =C3*E3 -> 0 | L3: =(F5+F30+F43+F60+F81+F141) -> 33.425359 | M3: Silvaplana (work)
A4: Surses (home) | B4: St. Moritz (work) | C4: 13 | E4: 0.2 | F4: =C4*E4 -> 2.6 | J4: yes | L4: =(F42+F59+F80) -> 6.6896116 | M4: Sils im Engadin/Segl (work)
A5: Surses (home) | B5: Silvaplana (work) | C5: 7 | E5: 0.2 | F5: =C5*E5 -> 1.4 | J5: yes | L5: =(F6) -> 1 | M5: Bregaglia (work)
A6: Surses (home) | B6: Bregaglia (work) | C6: 5 | E6: 0.2 | F6: =C6*E6 -> 1 | J6: yes
A7: Brusio (home) | B7: Pontresina (work) | C7: 9 | F7: =C7*E7 -> 0
A8: Brusio (home) | B8: Samedan (work) | C8: 27 | F8: =C8*E8 -> 0
A9: Brusio (home) | B9: St. Moritz (work) | C9: 27 | E9: 0.2 | F9: =C9*E9 -> 5.4 | J9: yes
A10: Poschiavo (home) | B10: Celerina/Schlarigna (work) | C10: 6 | F10: =C10*E10 -> 0
A11: Poschiavo (home) | B11: Pontresina (work) | C11: 56 | F11: =C11*E11 -> 0
A12: Poschiavo (home) | B12: Samedan (work) | C12: 45 | F12: =C12*E12 -> 0
A13: Poschiavo (home) | B13: St. Moritz (work) | C13: 55 | E13: 0.2 | F13: =C13*E13 -> 11 | J13: yes
A14: Domat/Ems (home) | B14: St. Moritz (work) | C14: 8 | E14: 0.2 | F14: =C14*E14 -> 1.6 | J14: yes
A15: Zernez (home) | B15: Bever (work) | C15: 8 | F15: =C15*E15 -> 0
A16: Zernez (home) | B16: Celerina/Schlarigna (work) | C16: 5 | F16: =C16*E16 -> 0
A17: Zernez (home) | B17: Pontresina (work) | C17: 9 | F17: =C17*E17 -> 0
A18: Zernez (home) | B18: La Punt Chamues-ch (work) | C18: 5 | F18: =C18*E18 -> 0
A19: Zernez (home) | B19: Samedan (work) | C19: 49 | F19: =C19*E19 -> 0
A20: Zernez (home) | B20: St. Moritz (work) | C20: 43 | E20: 0.2 | F20: =C20*E20 -> 8.6 | J20: yes
A21: Zernez (home) | B21: S-chanf (work) | C21: 17 | F21: =C21*E21 -> 0
A22: Zernez (home) | B22: Zuoz (work) | C22: 41 | F22: =C22*E22 -> 0
A23: Scuol (home) | B23: Samedan (work) | C23: 19 | F23: =C23*E23 -> 0
A24: Scuol (home) | B24: St. Moritz (work) | C24: 41 | E24: 0.2 | F24: =C24*E24 -> 8.2 | J24: yes
A25: Scuol (home) | B25: Zuoz (work) | C25: 15 | F25: =C25*E25 -> 0
A26: Bever (home) | B26: Thusis (work) | C26: 5 | D26: ='Population change 2018 to 2024'!$D$2*'Laborforce adjustment'!C26 -> 5.13382 | E26: 0.2 | F26: =E26*D26 -> 1.026764
A27: Bever (home) | B27: Bever (work) | C27: 113 | D27: ='Population change 2018 to 2024'!$D$2*'Laborforce adjustment'!C27 -> 116.02433 | F27: =E27*D27 -> 0
A28: Bever (home) | B28: Celerina/Schlarigna (work) | C28: 7 | D28: ='Population change 2018 to 2024'!$D$2*'Laborforce adjustment'!C28 -> 7.1873479 | E28: 0.2 | F28: =E28*D28 -> 1.4374696
A29: Bever (home) | B29: Pontresina (work) | C29: 25 | D29: ='Population change 2018 to 2024'!$D$2*'Laborforce adjustment'!C29 -> 25.6691 | E29: 0.2 | F29: =E29*D29 -> 5.13382
A30: Bever (home) | B30: Samedan (work) | C30: 88 | D30: ='Population change 2018 to 2024'!$D$2*'Laborforce adjustment'!C30 -> 90.355231 | E30: 0.2 | F30: =E30*D30 -> 18.071046
A31: Bever (home) | B31: St. Moritz (work) | C31: 49 | D31: ='Population change 2018 to 2024'!$D$2*'Laborforce adjustment'!C31 -> 50.311436 | E31: 0.2 | F31: =E31*D31 -> 10.062287 | J31: yes
A32: Bever (home) | B32: Silvaplana (work) | C32: 9 | D32: ='Population change 2018 to 2024'!$D$2*'Laborforce adjustment'!C32 -> 9.2408759 | E32: 0.2 | F32: =E32*D32 -> 1.8481752 | J32: yes
A33: Bever (home) | B33: Zuoz (work) | C33: 8 | D33: ='Population change 2018 to 2024'!$D$2*'Laborforce adjustment'!C33 -> 8.2141119 | E33: 0.2 | F33: =E33*D33 -> 1.6428224
A34: Bever (home) | B34: Chur (work) | C34: 7 | D34: ='Population change 2018 to 2024'!$D$2*'Laborforce adjustment'!C34 -> 7.1873479 | E34: 0.2 | F34: =E34*D34 -> 1.4374696
A35: Bever (home) | B35: Unknown (work) | C35: 14 | D35: ='Population change 2018 to 2024'!$D$2*'Laborforce adjustment'!C35 -> 14.374696 | E35: 0.2 | F35: =E35*D35 -> 2.8749392
A36: Bever (home) | B36: Unknown (work) | C36: 4 | D36: ='Population change 2018 to 2024'!$D$2*'Laborforce adjustment'!C36 -> 4.107056 | E36: 0.2 | F36: =E36*D36 -> 0.82141119
A37: Celerina/Schlarigna (home) | B37: Unknown (work) | C37: 5 | D37: ='Population change 2018 to 2024'!$D$4*C37 -> 4.5581172 | E37: 0.2 | F37: =E37*D37 -> 0.91162344
A38: Celerina/Schlarigna (home) | B38: Celerina/Schlarigna (work) | C38: 349 | D38: ='Population change 2018 to 2024'!$D$4*C38 -> 318.15658 | F38: =E38*D38 -> 0
A39: Celerina/Schlarigna (home) | B39: Pontresina (work) | C39: 45 | D39: ='Population change 2018 to 2024'!$D$4*C39 -> 41.023055 | E39: 0.2 | F39: =E39*D39 -> 8.204611
A40: Celerina/Schlarigna (home) | B40: Samedan (work) | C40: 124 | D40: ='Population change 2018 to 2024'!$D$4*C40 -> 113.04131 | E40: 0.2 | F40: =E40*D40 -> 22.608261
...
