Workbook

Sheet hotel alldata
A1: month | B1: tourist arrivals in hotels for the Maloja district per month (Htadm) | C1: tourist overnight stays in hotels in the Maloja district per month (Htodm) | D1: number of days in the month (Ndm) | E1: tourist average number of overnight stays per arrival in hotels in the Maloja district (Ntaoad) | F1: average number of tourist per night in hotels in the Maloja district (Atnh) | G1: average number of arrivals and departures in hotels in the Maloja district (Aad)
A2: 45323 | B2: 68236 | C2: 254496 | D2: 29 | E2: =C2/B2 -> 3.7296442 | F2: =B2/(D2/E2) -> 8775.7241 | G2: =(B2/D2)*2 -> 4705.931
A3: 45505 | B3: 74875 | C3: 209937 | D3: 31 | E3: =C3/B3 -> 2.8038331 | F3: =B3/(D3/E3) -> 6772.1613 | G3: =(B3/D3)*2 -> 4830.6452
A4: 45597 | B4: 18074 | C4: 36859 | D4: 30 | E4: =C4/B4 -> 2.0393383 | F4: =B4/(D4/E4) -> 1228.6333 | G4: =(B4/D4)*2 -> 1204.9333

Sheet hotel studyarea
A1: month | B1: tourist arrivals in hotels for the Maloja district per month (Htadm) | C1: tourist overnight stays in hotels in the Maloja district per month (Htodm) | D1: number of days in the month (Ndm) | E1: tourist average number of overnight stays per arrival in hotels in the Maloja district (Ntaoad) | F1: average number of tourist per night in hotels in the Maloja district (Atnh) | G1: average number of arrivals and departures in hotels in the Maloja district (Aad)
A2: 45323 | B2: 66707 | C2: 248763 | D2: 29 | E2: =C2/B2 -> 3.7291888 | F2: =B2/(D2/E2) -> 8578.0345 | G2: =(B2/D2)*2 -> 4600.4828
A3: 45505 | B3: 73259 | C3: 206231 | D3: 31 | E3: =C3/B3 -> 2.8150944 | F3: =B3/(D3/E3) -> 6652.6129 | G3: =(B3/D3)*2 -> 4726.3871
A4: 45597 | B4: 17726 | C4: 36085 | D4: 30 | E4: =C4/B4 -> 2.0357103 | F4: =B4/(D4/E4) -> 1202.8333 | G4: =(B4/D4)*2 -> 1181.7333

Sheet hotel finalarea
A1: month | B1: tourist arrivals in hotels for the Maloja district per month (Htadm) | C1: tourist overnight stays in hotels in the Maloja district per month (Htodm) | D1: number of days in the month (Ndm) | E1: tourist average number of overnight stays per arrival in hotels in the Maloja district (Ntaoad) | F1: average number of tourist per night in hotels in the Maloja district (Atnh) | G1: average number of arrivals and departures in hotels in the Maloja district (Aad)
A2: 45323 | B2: 42777 | C2: 165513 | D2: 29 | E2: =C2/B2 -> 3.8692054 | F2: =B2/(D2/E2) -> 5707.3448 | G2: =(B2/D2)*2 -> 2950.1379
A3: 45505 | B3: 49778 | C3: 137039 | D3: 31 | E3: =C3/B3 -> 2.7530033 | F3: =B3/(D3/E3) -> 4420.6129 | G3: =(B3/D3)*2 -> 3211.4839
A4: 45597 | B4: 10274 | C4: 19650 | D4: 30 | E4: =C4/B4 -> 1.9125949 | F4: =B4/(D4/E4) -> 655 | G4: =(B4/D4)*2 -> 684.93333
A6: municipality | B6: month | C6: tourist arrivals in hotels | D6: tourist overnight stays in hotels | E6: tourist average number of overnight stays per arrival in hotels | F6: average number of tourist per night in hotels | G6: average number of arrivals and departures in hotels | H6: average number of arrivals or departures in hotels
A7: Sils im Engadin/Segl | B7: 45323 | C7: 7607 | D7: 33359 | E7: =D7/C7 -> 4.385303 | F7: =C7/(29/E7) -> 1150.3103 | G7: =(C7/29)*2 -> 524.62069 | H7: =G7/2 -> 262.31034
B8: 45505 | C8: 7347 | D8: 28885 | E8: =D8/C8 -> 3.9315367 | F8: =C8/(31/E8) -> 931.77419 | G8: =(C8/31)*2 -> 474 | H8: =G8/2 -> 237
B9: 45597 | C9: 455 | D9: 906 | E9: =D9/C9 -> 1.9912088 | F9: =C9/(30/E9) -> 30.2 | G9: =(C9/30)*2 -> 30.333333 | H9: =G9/2 -> 15.166667
A10: Silvaplana | B10: 45323 | C10: 3610 | D10: 13348 | E10: =D10/C10 -> 3.6975069 | F10: =C10/(29/E10) -> 460.27586 | G10: =(C10/29)*2 -> 248.96552 | H10: =G10/2 -> 124.48276
B11: 45505 | C11: 3403 | D11: 10514 | E11: =D11/C11 -> 3.0896268 | F11: =C11/(31/E11) -> 339.16129 | G11: =(C11/31)*2 -> 219.54839 | H11: =G11/2 -> 109.77419
B12: 45597 | C12: 945 | D12: 2224 | E12: =D12/C12 -> 2.3534392 | F12: =C12/(30/E12) -> 74.133333 | G12: =(C12/30)*2 -> 63 | H12: =G12/2 -> 31.5
A13: Bregaglia | B13: 45323 | C13: 2225 | D13: 6692 | E13: =D13/C13 -> 3.0076404 | F13: =C13/(29/E13) -> 230.75862 | G13: =(C13/29)*2 -> 153.44828 | H13: =G13/2 -> 76.724138
B14: 45505 | C14: 4315 | D14: 10753 | E14: =D14/C14 -> 2.4920046 | F14: =C14/(31/E14) -> 346.87097 | G14: =(C14/31)*2 -> 278.3871 | H14: =G14/2 -> 139.19355
B15: 45597 | C15: 193 | D15: 427 | E15: =D15/C15 -> 2.2124352 | F15: =C15/(30/E15) -> 14.233333 | G15: =(C15/30)*2 -> 12.866667 | H15: =G15/2 -> 6.4333333
A16: St. Moritz | B16: 45323 | C16: 29335 | D16: 112114 | E16: =D16/C16 -> 3.821851 | F16: =C16/(29/E16) -> 3866 | G16: =(C16/29)*2 -> 2023.1034 | H16: =G16/2 -> 1011.5517
B17: 45505 | C17: 34713 | D17: 86887 | E17: =D17/C17 -> 2.5030104 | F17: =C17/(31/E17) -> 2802.8065 | G17: =(C17/31)*2 -> 2239.5484 | H17: =G17/2 -> 1119.7742
B18: 45597 | C18: 8681 | D18: 16093 | E18: =D18/C18 -> 1.8538187 | F18: =C18/(30/E18) -> 536.43333 | G18: =(C18/30)*2 -> 578.73333 | H18: =G18/2 -> 289.36667
C20: arrival/departure by public transportation rate | D20: tourists getting around by public transportation rate | E20: tourists visiting winter sports areas rate | F20: winter season other activities rate | G20: tourists visiting summer sports areas rate | H20: summer season other activities rate | I20: tourists visiting off season sports areas rate | J20: off season other activities rate
C21: 0.3 | D21: 0.15 | E21: 0.7 | F21: 0.3 | G21: 0.5 | H21: 0.5 | I21: 0.3 | J21: 0.7
A22: municipality | B22: month | C22: tourists arriving/departing by public transportation | D22: tourists going to winter sports areas by PT rate | E22: tourists visiting sports areas in the winter season by public transportation | F22: tourists visiting other activities in the winter season by public transportation | G22: tourists visiting sports areas in the summer season by public transportation | H22: tourists visiting other activities in the summer season by public transportation | I22: tourists visiting sports areas in the off season by public transportation | J22: tourists visiting other activities in the off season by public transportation
A23: Sils im Engadin/Segl | B23: 45323 | C23: =H7*C$21 -> 78.693103 | D23: 0.05 | E23: =((F7*2)*$E$21*($D$23))/2 -> 40.260862 | F23: =((F7*2)*$F$21*$D$21)/2/5 -> 10.352793
B24: 45505 | C24: =H8*C$21 -> 71.1 | G24: =(((F8-H8)*4+H8*2)*$G$21*$D$21)/2/7 -> 17.427304 | H24: =(((F8-H8)*4+H8*2)*$H$21*$D$21)/2/5 -> 24.398226
B25: 45597 | C25: =H9*C$21 -> 4.55 | I25: =((F9*2)*$I$21*$D$21)/2/4 -> 0.33975 | J25: =((F9*2)*$J$21*$D$21)/2/5 -> 0.6342
A26: Silvaplana | B26: 45323 | C26: =H10*C$21 -> 37.344828 | E26: =((F10*2)*$E$21*($D$23)/2) -> 16.109655 | F26: =((F10*2)*$F$21*$D$21)/2/5 -> 4.1424828
B27: 45505 | C27: =H11*C$21 -> 32.932258 | G27: =(((F11-H11)*4+H11*2)*$G$21*$D$21)/2/7 -> 6.0915899 | H27: =(((F11-H11)*4+H11*2)*$H$21*$D$21)/2/5 -> 8.5282258
B28: 45597 | C28: =H12*C$21 -> 9.45 | I28: =((F12*2)*$I$21*$D$21)/2/4 -> 0.834 | J28: =((F12*2)*$J$21*$D$21)/2/5 -> 1.5568
A29: Bregaglia | B29: 45323 | C29: =H13*C$21 -> 23.017241 | E29: =((F13*2)*$E$21*($D$23))/2 -> 8.0765517 | F29: =((F13*2)*$F$21*$D$21)/2/5 -> 2.0768276
B30: 45505 | C30: =H14*C$21 -> 41.758065 | G30: =(((F14-H14)*4+H14*2)*$G$21*$D$21)/2/7 -> 5.9415899 | H30: =(((F14-H14)*4+H14*2)*$H$21*$D$21)/2/5 -> 8.3182258
B31: 45597 | C31: =H15*C$21 -> 1.93 | I31: =((F15*2)*$I$21*$D$21)/2/4 -> 0.160125 | J31: =((F15*2)*$J$21*$D$21)/2/5 -> 0.2989
A32: St. Moritz | B32: 45323 | C32: =H16*C$21 -> 303.46552 | E32: =((F16*2)*$E$21*($D$23))/2 -> 135.31 | F32: =((F16*2)*$F$21*$D$21)/2/5 -> 34.794
B33: 45505 | C33: =H17*C$21 -> 335.93226 | G33: =(((F17-H17)*4+H17*2)*$G$21*$D$21)/2/7 -> 48.062558 | H33: =(((F17-H17)*4+H17*2)*$H$21*$D$21)/2/5 -> 67.287581
B34: 45597 | C34: =H18*C$21 -> 86.81 | I34: =((F18*2)*$I$21*$D$21)/2/4 -> 6.034875 | J34: =((F18*2)*$J$21*$D$21)/2/5 -> 11.2651
A37: month | B37: total PT demand
A38: 45323 | B38: =(40+16+8+135)*2+(10+4+2+35)*5*2+(79+37+23+303)*2 -> 1792
A39: 45505 | B39: =(17+6+6+48)*4*2+(24+9+8+67)*5*2+(71+33+42+336)*2 -> 2660
A40: 45597 | B40: =(6+1+1+1)*4*2+(11+1+2+1)*5*2+(5+9+2+87)*2 -> 428

Sheet hotel overnightstay customcurve
B1: all data
B2: original overnight stays in hotels per month (Todm) | C2: original overnight stays in hotels per month ratio | D2: customized overnight stays in hotels per month (Todm) | E2: customized overnight stays in hotels per month ratio
A3: 2024-01 | B3: 226054 | C3: =B3/SUM($B$3:$B$14) -> 0.13006978 | D3: =$B$6 -> 43423 | E3: =D3/SUM($D$3:$D$14) -> 0.041168919
A4: 2024-02 | B4: 254496 | C4: =B4/SUM($B$3:$B$14) -> 0.1464351 | D4: =$B$6 -> 43423 | E4: =D4/SUM($D$3:$D$14) -> 0.041168919
A5: 2024-03 | B5: 194441 | C5: =B5/SUM($B$3:$B$14) -> 0.1118799 | D5: =$B$6 -> 43423 | E5: =D5/SUM($D$3:$D$14) -> 0.041168919
A6: 2024-04 | B6: 43423 | C6: =B6/SUM($B$3:$B$14) -> 0.02498527 | D6: =$B$6 -> 43423 | E6: =D6/SUM($D$3:$D$14) -> 0.041168919
A7: 2024-05 | B7: 40450 | C7: =B7/SUM($B$3:$B$14) -> 0.023274628 | D7: =B7 -> 40450 | E7: =D7/SUM($D$3:$D$14) -> 0.038350247
A8: 2024-06 | B8: 111268 | C8: =B8/SUM($B$3:$B$14) -> 0.064022776 | D8: =B8 -> 111268 | E8: =D8/SUM($D$3:$D$14) -> 0.1054921
A9: 2024-07 | B9: 196361 | C9: =B9/SUM($B$3:$B$14) -> 0.11298465 | D9: =B9 -> 196361 | E9: =D9/SUM($D$3:$D$14) -> 0.18616793
A10: 2024-08 | B10: 209937 | C10: =B10/SUM($B$3:$B$14) -> 0.12079618 | D10: =B10 -> 209937 | E10: =D10/SUM($D$3:$D$14) -> 0.19903921
A11: 2024-09 | B11: 137769 | C11: =B11/SUM($B$3:$B$14) -> 0.079271254 | D11: =B11 -> 137769 | E11: =D11/SUM($D$3:$D$14) -> 0.13061743
A12: 2024-10 | B12: 107966 | C12: =B12/SUM($B$3:$B$14) -> 0.06212283 | D12: =B12 -> 107966 | E12: =D12/SUM($D$3:$D$14) -> 0.1023615
A13: 2024-11 | B13: 36859 | C13: =B13/SUM($B$3:$B$14) -> 0.021208393 | D13: =B13 -> 36859 | E13: =D13/SUM($D$3:$D$14) -> 0.034945655
A14: 2024-12 | B14: 178920 | C14: =B14/SUM($B$3:$B$14) -> 0.10294923 | D14: =B7 -> 40450 | E14: =D14/SUM($D$3:$D$14) -> 0.038350247
B17: study area
B18: original overnight stays in hotels per month (Todm) | C18: original overnight stays in hotels per month ratio | D18: customized overnight stays in hotels per month (Todm) | E18: customized overnight stays in hotels per month ratio
A19: 2024-01 | B19: 221945 | C19: =B19/SUM($B$3:$B$14) -> 0.1277055 | D19: =$B$22 -> 42774 | E19: =D19/SUM($D$3:$D$14) -> 0.040553609
A20: 2024-02 | B20: 248763 | C20: =B20/SUM($B$3:$B$14) -> 0.14313637 | D20: =$B$22 -> 42774 | E20: =D20/SUM($D$3:$D$14) -> 0.040553609
A21: 2024-03 | B21: 192009 | C21: =B21/SUM($B$3:$B$14) -> 0.11048054 | D21: =$B$22 -> 42774 | E21: =D21/SUM($D$3:$D$14) -> 0.040553609
A22: 2024-04 | B22: 42774 | C22: =B22/SUM($B$3:$B$14) -> 0.02461184 | D22: =$B$22 -> 42774 | E22: =D22/SUM($D$3:$D$14) -> 0.040553609
A23: 2024-05 | B23: 40050 | C23: =B23/SUM($B$3:$B$14) -> 0.023044471 | D23: =B23 -> 40050 | E23: =D23/SUM($D$3:$D$14) -> 0.037971011
A24: 2024-06 | B24: 109606 | C24: =B24/SUM($B$3:$B$14) -> 0.063066474 | D24: =B24 -> 109606 | E24: =D24/SUM($D$3:$D$14) -> 0.10391637
A25: 2024-07 | B25: 193136 | C25: =B25/SUM($B$3:$B$14) -> 0.11112901 | D25: =B25 -> 193136 | E25: =D25/SUM($D$3:$D$14) -> 0.18311034
A26: 2024-08 | B26: 206231 | C26: =B26/SUM($B$3:$B$14) -> 0.11866378 | D26: =B26 -> 206231 | E26: =D26/SUM($D$3:$D$14) -> 0.19552558
A27: 2024-09 | B27: 135187 | C27: =B27/SUM($B$3:$B$14) -> 0.07778559 | D27: =B27 -> 135187 | E27: =D27/SUM($D$3:$D$14) -> 0.12816947
A28: 2024-10 | B28: 106002 | C28: =B28/SUM($B$3:$B$14) -> 0.060992759 | D28: =B28 -> 106002 | E28: =D28/SUM($D$3:$D$14) -> 0.10049945
A29: 2024-11 | B29: 36085 | C29: =B29/SUM($B$3:$B$14) -> 0.02076304 | D29: =B29 -> 36085 | E29: =D29/SUM($D$3:$D$14) -> 0.034211834
A30: 2024-12 | B30: 175932 | C30: =B30/SUM($B$3:$B$14) -> 0.10122996 | D30: =B23 -> 40050 | E30: =D30/SUM($D$3:$D$14) -> 0.037971011
B33: final area
B34: original overnight stays in hotels per month (Todm) | C34: original overnight stays in hotels per month ratio | D34: customized overnight stays in hotels per month (Todm) | E34: customized overnight stays in hotels per month ratio
A35: 2024-01 | B35: 150700 | C35: =B35/SUM($B$3:$B$14) -> 0.086711655 | D35: =$B$38 -> 30547 | E35: =D35/SUM($D$3:$D$14) -> 0.02896131
A36: 2024-02 | B36: 165513 | C36: =B36/SUM($B$3:$B$14) -> 0.095234944 | D36: =$B$38 -> 30547 | E36: =D36/SUM($D$3:$D$14) -> 0.02896131
A37: 2024-03 | B37: 130541 | C37: =B37/SUM($B$3:$B$14) -> 0.075112317 | D37: =$B$38 -> 30547 | E37: =D37/SUM($D$3:$D$14) -> 0.02896131
A38: 2024-04 | B38: 30547 | C38: =B38/SUM($B$3:$B$14) -> 0.017576516 | D38: =$B$38 -> 30547 | E38: =D38/SUM($D$3:$D$14) -> 0.02896131
A39: 2024-05 | B39: 31077 | C39: =B39/SUM($B$3:$B$14) -> 0.017881474 | D39: =B39 -> 31077 | E39: =D39/SUM($D$3:$D$14) -> 0.029463798
A40: 2024-06 | B40: 74324 | C40: =B40/SUM($B$3:$B$14) -> 0.042765475 | D40: =B40 -> 74324 | E40: =D40/SUM($D$3:$D$14) -> 0.070465854
A41: 2024-07 | B41: 127489 | C41: =B41/SUM($B$3:$B$14) -> 0.073356219 | D41: =B41 -> 127489 | E41: =D41/SUM($D$3:$D$14) -> 0.12087107
A42: 2024-08 | B42: 137039 | C42: =B42/SUM($B$3:$B$14) -> 0.078851217 | D42: =B42 -> 137039 | E42: =D42/SUM($D$3:$D$14) -> 0.12992533
A43: 2024-09 | B43: 84694 | C43: =B43/SUM($B$3:$B$14) -> 0.048732295 | D43: =B43 -> 84694 | E43: =D43/SUM($D$3:$D$14) -> 0.080297549
A44: 2024-10 | B44: 58539 | C44: =B44/SUM($B$3:$B$14) -> 0.033682903 | D44: =B44 -> 58539 | E44: =D44/SUM($D$3:$D$14) -> 0.05550025
...

Sheet non-hotel alldata
A1: month | B1: tourist arrivals in non hotels in the Maloja district per month (Ntadm) | C1: tourist overnight stays in non hotels in the Maloja district per month (Ntodm) | D1: tourist average number of overnight stays per arrival in non hotels in the Maloja district (Ntaoad) | E1: average number of tourist per night in non hotels in the Maloja district (Natnd) | F1: average number of arrivals and departures in non hotels in the Maloja district (Naadd)
A2: 45323 | B2: =$B$12*($C$12/$D$12)*(B7/$C$12) -> 19542.798 | C2: =($B$15*($C$15/$D$15)*(C7/$C$15)) -> 131219.28 | D2: =C2/B2 -> 6.7144573 | E2: =B2/(29/D2) -> 4524.8029 | F2: =(B2/29)*2 -> 1347.7792
A3: 45505 | B3: =$B$12*($C$12/$D$12)*(B8/$C$12) -> 21444.208 | C3: =($B$15*($C$15/$D$15)*(C8/$C$15)) -> 108244.46 | D3: =C3/B3 -> 5.0477248 | E3: =B3/(31/D3) -> 3491.7569 | F3: =(B3/31)*2 -> 1383.4973
A4: 45597 | B4: =$B$12*($C$12/$D$12)*(B9/$C$12) -> 5176.3956 | C4: =($B$15*($C$15/$D$15)*(C9/$C$15)) -> 19004.666 | D4: =C4/B4 -> 3.6714092 | E4: =B4/(30/D4) -> 633.48888 | F4: =(B4/30)*2 -> 345.09304
A6: month | B6: tourist arrivals in hotels in the Maloja district per month (Htadm) | C6: tourist overnight stays in hotels in the Maloja district per month (Htodm)
A7: 45323 | B7: ='hotel alldata'!B2 -> 68236 | C7: ='hotel alldata'!C2 -> 254496
A8: 45505 | B8: ='hotel alldata'!B3 -> 74875 | C8: ='hotel alldata'!C3 -> 209937
A9: 45597 | B9: ='hotel alldata'!B4 -> 18074 | C9: ='hotel alldata'!C4 -> 36859
B11: tourist arrivals in non hotels in the canton of Grisons per year (Ntacy) | C11: tourist arrivals in hotels in the Maloja district per year (Htady) | D11: tourist arrivals in hotels in the canton of Grisons per year (Htacy)
B12: 608858.57 | C12: 608535 | D12: 2125902
B14: tourist overnight stays in non hotels for the canton of Grisons per year (Ntocy) | C14: tourist overnight stays in hotels in the Maloja district per year (Htody) | D14: tourist overnight stays in hotels in the canton of Grisons per year (Htocy)
B15: 2849765.7 | C15: 1737944 | D15: 5527038

Sheet non-hotel studyarea
A1: month | B1: tourist arrivals in non hotels in the Maloja district per month (Ntadm) | C1: tourist overnight stays in non hotels in the Maloja district per month (Ntodm) | D1: tourist average number of overnight stays per arrival in non hotels in the Maloja district (Ntaoad) | E1: average number of tourist per night in non hotels in the Maloja district (Natnd) | F1: average number of arrivals and departures in non hotels in the Maloja district (Naadd)
A2: 45323 | B2: =$B$12*($C$12/$D$12)*(B7/$C$12) -> 19104.892 | C2: =($B$15*($C$15/$D$15)*(C7/$C$15)) -> 128263.32 | D2: =C2/B2 -> 6.7136376 | E2: =B2/(29/D2) -> 4422.8732 | F2: =(B2/29)*2 -> 1317.5788
A3: 45505 | B3: =$B$12*($C$12/$D$12)*(B8/$C$12) -> 20981.386 | C3: =($B$15*($C$15/$D$15)*(C8/$C$15)) -> 106333.63 | D3: =C3/B3 -> 5.0679985 | E3: =B3/(31/D3) -> 3430.1172 | F3: =(B3/31)*2 -> 1353.6378
A4: 45597 | B4: =$B$12*($C$12/$D$12)*(B9/$C$12) -> 5076.7284 | C4: =($B$15*($C$15/$D$15)*(C9/$C$15)) -> 18605.589 | D4: =C4/B4 -> 3.6648777 | E4: =B4/(30/D4) -> 620.18628 | F4: =(B4/30)*2 -> 338.44856
A6: month | B6: tourist arrivals in hotels in the Maloja district per month (Htadm) | C6: tourist overnight stays in hotels in the Maloja district per month (Htodm)
A7: 45323 | B7: ='hotel studyarea'!B2 -> 66707 | C7: ='hotel studyarea'!C2 -> 248763
A8: 45505 | B8: ='hotel studyarea'!B3 -> 73259 | C8: ='hotel studyarea'!C3 -> 206231
A9: 45597 | B9: ='hotel studyarea'!B4 -> 17726 | C9: ='hotel studyarea'!C4 -> 36085
B11: tourist arrivals in non hotels in the canton of Grisons per year (Ntacy) | C11: tourist arrivals in hotels in the Maloja district per year (Htady) | D11: tourist arrivals in hotels in the canton of Grisons per year (Htacy)
B12: 608858.57 | C12: 596520 | D12: 2125902
B14: tourist overnight stays in non hotels for the canton of Grisons per year (Ntocy) | C14: tourist overnight stays in hotels in the Maloja district per year (Htody) | D14: tourist overnight stays in hotels in the canton of Grisons per year (Htocy)
B15: 2849765.7 | C15: 1707720 | D15: 5527038

Sheet non-hotel finalarea
A1: month | B1: tourist arrivals in non hotels in the Maloja district per month (Ntadm) | C1: tourist overnight stays in non hotels in the Maloja district per month (Ntodm) | D1: tourist average number of overnight stays per arrival in non hotels in the Maloja district (Ntaoad) | E1: average number of tourist per night in non hotels in the Maloja district (Natnd) | F1: average number of arrivals and departures in non hotels in the Maloja district (Naadd)
A2: 45323 | B2: =$B$12*($C$12/$D$12)*(B7/$C$12) -> 12251.338 | C2: =($B$15*($C$15/$D$15)*(C7/$C$15)) -> 85339.248 | D2: =C2/B2 -> 6.9657086 | E2: =B2/(29/D2) -> 2942.7327 | F2: =(B2/29)*2 -> 844.91984
A3: 45505 | B3: =$B$12*($C$12/$D$12)*(B8/$C$12) -> 14256.425 | C3: =($B$15*($C$15/$D$15)*(C8/$C$15)) -> 70657.926 | D3: =C3/B3 -> 4.9562163 | E3: =B3/(31/D3) -> 2279.2879 | F3: =(B3/31)*2 -> 919.76934
A4: 45597 | B4: =$B$12*($C$12/$D$12)*(B9/$C$12) -> 2942.4748 | C4: =($B$15*($C$15/$D$15)*(C9/$C$15)) -> 10131.628 | D4: =C4/B4 -> 3.4432338 | E4: =B4/(30/D4) -> 337.72095 | F4: =(B4/30)*2 -> 196.16498
A6: month | B6: tourist arrivals in hotels in the Maloja district per month (Htadm) | C6: tourist overnight stays in hotels in the Maloja district per month (Htodm)
A7: 45323 | B7: ='hotel finalarea'!B2 -> 42777 | C7: ='hotel finalarea'!C2 -> 165513
A8: 45505 | B8: ='hotel finalarea'!B3 -> 49778 | C8: ='hotel finalarea'!C3 -> 137039
A9: 45597 | B9: ='hotel finalarea'!B4 -> 10274 | C9: ='hotel finalarea'!C4 -> 19650
B11: tourist arrivals in non hotels in the canton of Grisons per year (Ntacy) | C11: tourist arrivals in hotels in the Maloja district per year (Htady) | D11: tourist arrivals in hotels in the canton of Grisons per year (Htacy)
B12: 608858.57 | C12: 401628 | D12: 2125902
B14: tourist overnight stays in non hotels for the canton of Grisons per year (Ntocy) | C14: tourist overnight stays in hotels in the Maloja district per year (Htody) | D14: tourist overnight stays in hotels in the canton of Grisons per year (Htocy)
B15: 2849765.7 | C15: 1132262 | D15: 5527038
D17: arrival/departure by public transportation rate | E17: tourists getting around by public transportation rate | F17: grocery shopping on arrival rate | G17: tourists visiting winter sports areas rate | H17: winter season other activities rate | I17: tourists visiting summer sports areas rate | J17: summer season other activities rate | K17: tourists visiting off season sports areas rate | L17: off season other activities rate
D18: 0.3 | E18: 0.15 | F18: 0.1 | G18: 0.7 | H18: 0.3 | I18: 0.5 | J18: 0.5 | K18: 0.3 | L18: 0.7
A19: municipality | B19: month | C19: average number of arrivals or departures in non hotels in the Maloja district | D19: average number of tourist per night in non hotels in the Maloja district | E19: tourists arriving/departing by public transportation | F19: tourists going grocery shopping by public transportation | G19: tourists visiting sports areas in the winter season by public transportation | H19: tourists visiting other activities in the winter season by public transportation | I19: tourists visiting sports areas in the summer season by public transportation | J19: tourists visiting other activities in the summer season by public transportation | K19: tourists visiting sports areas in the off season by public transportation | L19: tourists visiting other activities in the off season by public transportation
A20: Sils im Engadin/Segl | B20: 45323 | C20: =$F$2*'hotel finalarea'!C7/$B$7/2 -> 75.125712 | D20: =$E$2*'hotel finalarea'!D7/$C$7 -> 593.10519 | E20: =C20*D$18 -> 22.537714 | F20: =C20*$F$18*$E$18 -> 1.1268857 | G20: =((D20*2)*$E$18*$G$18)/2 -> 62.276045 | H20: =((D20*2)*$E$18*$H$18)/2/5 -> 5.3379467
B21: 45505 | C21: =$F$3*'hotel finalarea'!C8/$B$8/2 -> 67.876827 | D21: =$E$3*'hotel finalarea'!D8/$C$8 -> 480.42697 | E21: =C21*D$18 -> 20.363048 | F21: =C21*$F$18*$E$18 -> 1.0181524 | I21: =((D21*2)*$I$18*$E$18)/2/7 -> 5.1474318 | J21: =((D21*2)*$I$18*$E$18)/2/5 -> 7.2064046
B22: 45597 | C22: =$F$4*'hotel finalarea'!C9/$B$9/2 -> 4.343735 | D22: =$E$4*'hotel finalarea'!D9/$C$9 -> 15.571256 | E22: =C22*D$18 -> 1.3031205 | F22: =C22*$F$18*$E$18 -> 0.065156026 | K22: =((D22*2)*$K$18*$E$18)/2/4 -> 0.17517663 | L22: =((D22*2)*$L$18*$E$18)/2/5 -> 0.32699638
A23: Silvaplana | B23: 45323 | C23: =$F$2*'hotel finalarea'!C10/$B$7/2 -> 35.651876 | D23: =$E$2*'hotel finalarea'!D10/$C$7 -> 237.32031 | E23: =C23*D$18 -> 10.695563 | F23: =C23*$F$18*$E$18 -> 0.53477814 | G23: =((D23*2)*$E$18*$G$18)/2 -> 24.918632 | H23: =((D23*2)*$E$18*$H$18)/2/5 -> 2.1358828
B24: 45505 | C24: =$F$3*'hotel finalarea'!C11/$B$8/2 -> 31.439341 | D24: =$E$3*'hotel finalarea'!D11/$C$8 -> 174.87309 | E24: =C24*D$18 -> 9.4318024 | F24: =C24*$F$18*$E$18 -> 0.47159012 | I24: =((D24*2)*$I$18*$E$18)/2/7 -> 1.8736402 | J24: =((D24*2)*$I$18*$E$18)/2/5 -> 2.6230963
B25: 45597 | C25: =$F$4*'hotel finalarea'!C12/$B$9/2 -> 9.0216035 | D25: =$E$4*'hotel finalarea'!D12/$C$9 -> 38.223481 | E25: =C25*D$18 -> 2.7064811 | F25: =C25*$F$18*$E$18 -> 0.13532405 | K25: =((D25*2)*$K$18*$E$18)/2/4 -> 0.43001416 | L25: =((D25*2)*$L$18*$E$18)/2/5 -> 0.80269309
A26: Bregaglia | B26: 45323 | C26: =$F$2*'hotel finalarea'!C13/$B$7/2 -> 21.973802 | D26: =$E$2*'hotel finalarea'!D13/$C$7 -> 118.98018 | E26: =C26*D$18 -> 6.5921405 | F26: =C26*$F$18*$E$18 -> 0.32960703 | G26: =((D26*2)*$E$18*$G$18)/2 -> 12.492919 | H26: =((D26*2)*$E$18*$H$18)/2/5 -> 1.0708217
B27: 45505 | C27: =$F$3*'hotel finalarea'!C14/$B$8/2 -> 39.865048 | D27: =$E$3*'hotel finalarea'!D14/$C$8 -> 178.84823 | E27: =C27*D$18 -> 11.959514 | F27: =C27*$F$18*$E$18 -> 0.59797572 | I27: =((D27*2)*$I$18*$E$18)/2/7 -> 1.9162311 | J27: =((D27*2)*$I$18*$E$18)/2/5 -> 2.6827235
B28: 45597 | C28: =$F$4*'hotel finalarea'!C15/$B$9/2 -> 1.8425074 | D28: =$E$4*'hotel finalarea'!D15/$C$9 -> 7.3387708 | E28: =C28*D$18 -> 0.55275222 | F28: =C28*$F$18*$E$18 -> 0.027637611 | K28: =((D28*2)*$K$18*$E$18)/2/4 -> 0.082561171 | L28: =((D28*2)*$L$18*$E$18)/2/5 -> 0.15411419
A29: St. Moritz | B29: 45323 | C29: =$F$2*'hotel finalarea'!C16/$B$7/2 -> 289.70853 | D29: =$E$2*'hotel finalarea'!D16/$C$7 -> 1993.327 | E29: =C29*D$18 -> 86.912558 | F29: =C29*$F$18*$E$18 -> 4.3456279 | G29: =((D29*2)*$E$18*$G$18)/2 -> 209.29934 | H29: =((D29*2)*$E$18*$H$18)/2/5 -> 17.939943
B30: 45505 | C30: =$F$3*'hotel finalarea'!C17/$B$8/2 -> 320.70346 | D30: =$E$3*'hotel finalarea'!D17/$C$8 -> 1445.1396 | E30: =C30*D$18 -> 96.211037 | F30: =C30*$F$18*$E$18 -> 4.8105518 | I30: =((D30*2)*$I$18*$E$18)/2/7 -> 15.483639 | J30: =((D30*2)*$I$18*$E$18)/2/5 -> 21.677094
B31: 45597 | C31: =$F$4*'hotel finalarea'!C18/$B$9/2 -> 82.874646 | D31: =$E$4*'hotel finalarea'!D18/$C$9 -> 276.58744 | E31: =C31*D$18 -> 24.862394 | F31: =C31*$F$18*$E$18 -> 1.2431197 | K31: =((D31*2)*$K$18*$E$18)/2/4 -> 3.1116087 | L31: =((D31*2)*$L$18*$E$18)/2/5 -> 5.8083363
A33: month | B33: total PT demand
A34: 45323 | B34: =(1+1+1+4)*2+(62+25+12+209)*2+(5+2+2+15)*5*2+(23+11+3+87)*2 -> 1118
A35: 45505 | B35: =(1+1+1+5)*2+(5+2+2+15)*4*2+(7+3+3+22)*5*2+(20+9+12+96)*2 -> 832
A36: 45597 | B36: =(1+1+1+1)*2+(1+1+1+3)*4*2+(1+1+1+6)*5*2+(1+3+1+25)*2 -> 206

Sheet campgrounds
C1: short term | D1: long term | E1: total
A2: Camping Morteratsch | B2: all year | C2: 250 | D2: 80 | E2: 330
A3: TCS Camping Samedan | B3: all year | C3: 60 | D3: 50 | E3: 110
A4: Camping Mulina | B4: summer | C4: 140 | D4: 10 | E4: 150
A5: Camping St. Moritz | B5: summer | C5: 199 | D5: 0 | E5: 199
A6: Camping Madulain | B6: winter & summer | C6: 30 | D6: 10 | E6: 40
A7: Camping Silvaplana | B7: summer | C7: 130 | D7: 120 | E7: 250
A8: Camping Gravatscha | B8: all year | C8: 44 | D8: 12 | E8: 56
A9: Camping Maloja | B9: summer | C9: 110 | D9: 10 | E9: 120
A10: Camping Chapella | B10: summer | C10: 100 | D10: 20 | E10: 120
A12: all campsites | B12: winter | C12: =C2+C3+C6+C8 -> 384 | D12: =D2+D3+D6+D8 -> 152 | E12: =E2+E3+E6+E8 -> 536
C13: =C12/$E$12 -> 0.71641791 | D13: =D12/$E$12 -> 0.28358209 | E13: =E12/$E$12 -> 1
A14: all campsites | B14: summer | C14: =SUM(C2:C10) -> 1063 | D14: =SUM(D2:D10) -> 312 | E14: =SUM(E2:E10) -> 1375
C15: =C14/$E$14 -> 0.77309091 | D15: =D14/$E$14 -> 0.22690909 | E15: =E14/$E$14 -> 1
A16: all campsites | B16: off season | C16: =C2+C3+C8 -> 354 | D16: =D2+D3+D8 -> 142 | E16: =E2+E3+E8 -> 496
C17: =C16/$E$16 -> 0.71370968 | D17: =D16/$E$16 -> 0.28629032 | E17: =E16/$E$16 -> 1
A19: study area (without Madulain and Chapella) | B19: winter | C19: =C2+C3+C8 -> 354 | D19: =D2+D3+D8 -> 142 | E19: =E2+E3+E8 -> 496
C20: =C19/$E$19 -> 0.71370968 | D20: =D19/$E$19 -> 0.28629032 | E20: =E19/$E$19 -> 1
A21: study area (without Madulain and Chapella) | B21: summer | C21: =C2+C3+C4+C5+C7+C8+C9 -> 933 | D21: =D2+D3+D4+D5+D7+D8+D9 -> 282 | E21: =E2+E3+E4+E5+E7+E8+E9 -> 1215
C22: =C21/$E$21 -> 0.76790123 | D22: =D21/$E$21 -> 0.23209877 | E22: =E21/$E$21 -> 1
A23: study area (without Madulain and Chapella) | B23: off season | C23: =C2+C3+C8 -> 354 | D23: =D2+D3+D8 -> 142 | E23: =E2+E3+E8 -> 496
C24: =C23/$E$23 -> 0.71370968 | D24: =D23/$E$23 -> 0.28629032 | E24: =E23/$E$23 -> 1
A26: final area (only Maloja, Mulina, Silvaplana, St. Moritz) | B26: winter | C26: 0 | D26: 0 | E26: 0
C27: 0 | D27: 0 | E27: 0
A28: final area (only Maloja, Mulina, Silvaplana, St. Moritz) | B28: summer | C28: =C4+C5+C7+C9 -> 579 | D28: =D4+D5+D7+D9 -> 140 | E28: =E4+E5+E7+E9 -> 719
C29: =C28/$E$28 -> 0.80528512 | D29: =D28/$E$28 -> 0.19471488 | E29: =E28/$E$28 -> 1
A30: final area (only Maloja, Mulina, Silvaplana, St. Moritz) | B30: off season | C30: 0 | D30: 0 | E30: 0
C31: 0 | D31: 0 | E31: 0

Sheet campgrounds shortterm alldata
A1: month | B1: estimated duration of season in months (Ms) | C1: camping spots short term in the Maloja district for the selected month (Csdm) | D1: camping spots short term available in the canton of Grisons for the selected month (Csacm) | E1: campground arrivals at short term spots in the Maloja district as a monthly total (Casdmt) | F1: campground overnight stays at short term spots in the Maloja district as a monthly total (Cosdmt) | G1: average number of overnight stays per arrival at short term camping spots in the Maloja district (Ctaoad) | H1: number of days in the month (Ndm) | I1: average number of tourist per night at short term camping spots in the Maloja district (Catnd) | J1: average number of arrivals and departures at short term camping spots in the Maloja district (Caadd)
A2: 45323 | B2: 4 | C2: =campgrounds!C12 -> 384 | D2: =$E$7*(C2/$B$7) -> 1265.7912 | E2: =(C2/$C$10)*$D$10 -> 2867.7219 | F2: =(B13/$B$19)*$E$10 -> 6808.4629 | G2: =F2/E2 -> 2.3741713 | H2: 29 | I2: =E2/(H2/(F2/E2)) -> 234.77458 | J2: =(E2/H2)*2 -> 197.77392
A3: 45505 | B3: 5 | C3: =campgrounds!C14 -> 1063 | D3: =$E$7*(C3/$B$7) -> 3504 | E3: =(C3/$C$10)*$D$10 -> 7938.5114 | F3: =(B14/$B$19)*$E$10 -> 32916.848 | G3: =F3/E3 -> 4.1464761 | H3: 31 | I3: =E3/(H3/(F3/E3)) -> 1061.8338 | J3: =(E3/H3)*2 -> 512.16202
A4: 45597 | B4: 3 | C4: =campgrounds!C16 -> 354 | D4: =$E$7*(C4/$B$7) -> 1166.9012 | E4: =(C4/$C$10)*$D$10 -> 2643.6811 | F4: =(B15/$B$19)*$E$10 -> 5779.2675 | G4: =F4/E4 -> 2.1860683 | H4: 30 | I4: =E4/(H4/(F4/E4)) -> 192.64225 | J4: =(E4/H4)*2 -> 176.24541
B6: camping spots short term in the Maloja district in total (Csdt) | C6: campground arrivals at short term spots in the canton of Grisons in total (Casct) | D6: campground overnight stays at short term spots in the canton of Grisons in total (Cosct) | E6: camping spots short term in the canton of Grisons in total (Csct)
B7: 1063 | C7: 194795 | D7: 545143 | E7: 3504
B9: camping spots short term annual compound availability in the canton of Grisons (Csacc) | C9: camping spots short term annual compound availability in the Maloja district (Csacd) | D9: campground arrivals at short term spots in the Maloja district as an annual total (Casdt) | E9: campground arrivals at short term spots in the Maloja district as an annual total (Casdat)
B10: =D3*B3+D2*B2+D4*B4 -> 26083.868 | C10: =C3*B3+C2*B2+C4*B4 -> 7913 | D10: =C10*(C7/B10) -> 59094.488 | E10: =C10*(D7/B10) -> 165378.71
A12: month | B12: tourist overnight stays in hotels in the Maloja district per month customized curve (Htodmc)
A13: 45323 | B13: ='hotel overnightstay customcurve'!D4 -> 43423
A14: 45505 | B14: ='hotel overnightstay customcurve'!D10 -> 209937
A15: 45597 | B15: ='hotel overnightstay customcurve'!D13 -> 36859
B18: tourist overnight stays in hotels in the Maloja district per year customized curve (Htodyc)
B19: =SUM('hotel overnightstay customcurve'!D3:D14) -> 1054752

Sheet campgrounds shortterm studyarea
A1: month | B1: estimated duration of season in months (Ms) | C1: camping spots short term in the Maloja district for the selected month (Csdm) | D1: camping spots short term available in the canton of Grisons for the selected month (Csacm) | E1: campground arrivals at short term spots in the Maloja district as a monthly total (Casdmt) | F1: campground overnight stays at short term spots in the Maloja district as a monthly total (Cosdmt) | G1: average number of overnight stays per arrival at short term camping spots in the Maloja district (Ctaoad) | H1: number of days in the month (Ndm) | I1: average number of tourist per night at short term camping spots in the Maloja district (Catnd) | J1: average number of arrivals and departures at short term camping spots in the Maloja district (Caadd)
A2: 45323 | B2: 4 | C2: =campgrounds!C19 -> 354 | D2: =$E$7*(C2/$B$7) -> 1329.492 | E2: =(C2/$C$10)*$D$10 -> 2570.5021 | F2: =(B13/$B$19)*$E$10 -> 5984.7168 | G2: =F2/E2 -> 2.3282287 | H2: 29 | I2: =E2/(H2/(F2/E2)) -> 206.36955 | J2: =(E2/H2)*2 -> 177.27601
A3: 45505 | B3: 5 | C3: =campgrounds!C21 -> 933 | D3: =$E$7*(C3/$B$7) -> 3504 | E3: =(C3/$C$10)*$D$10 -> 6774.7979 | F3: =(B14/$B$19)*$E$10 -> 28854.775 | G3: =F3/E3 -> 4.2591344 | H3: 31 | I3: =E3/(H3/(F3/E3)) -> 930.79919 | J3: =(E3/H3)*2 -> 437.08374
A4: 45597 | B4: 3 | C4: =campgrounds!C23 -> 354 | D4: =$E$7*(C4/$B$7) -> 1329.492 | E4: =(C4/$C$10)*$D$10 -> 2570.5021 | F4: =(B15/$B$19)*$E$10 -> 5048.8266 | G4: =F4/E4 -> 1.9641402 | H4: 30 | I4: =E4/(H4/(F4/E4)) -> 168.29422 | J4: =(E4/H4)*2 -> 171.36681
B6: camping spots short term in the Maloja district in total (Csdt) | C6: campground arrivals at short term spots in the canton of Grisons in total (Casct) | D6: campground overnight stays at short term spots in the canton of Grisons in total (Cosct) | E6: camping spots short term in the canton of Grisons in total (Csct)
B7: 933 | C7: 194795 | D7: 545143 | E7: 3504
B9: camping spots short term annual compound availability in the canton of Grisons (Csacc) | C9: camping spots short term annual compound availability in the Maloja district (Csacd) | D9: campground arrivals at short term spots in the Maloja district as an annual total (Casdt) | E9: campground arrivals at short term spots in the Maloja district as an annual total (Casdat)
B10: =D3*B3+D2*B2+D4*B4 -> 26826.444 | C10: =C3*B3+C2*B2+C4*B4 -> 7143 | D10: =C10*(C7/B10) -> 51867.504 | E10: =C10*(D7/B10) -> 145153.66
A12: month | B12: tourist overnight stays in hotels in the Maloja district per month customized curve (Htodmc)
A13: 45323 | B13: ='hotel overnightstay customcurve'!D20 -> 42774
A14: 45505 | B14: ='hotel overnightstay customcurve'!D26 -> 206231
A15: 45597 | B15: ='hotel overnightstay customcurve'!D29 -> 36085
B18: tourist overnight stays in hotels in the Maloja district per year customized curve (Htodyc)
B19: =SUM('hotel overnightstay customcurve'!D19:D30) -> 1037443

Sheet campgrounds shortterm finalarea
A1: month | B1: estimated duration of season in months (Ms) | C1: camping spots short term in the Maloja district for the selected month (Csdm) | D1: camping spots short term available in the canton of Grisons for the selected month (Csacm) | E1: campground arrivals at short term spots in the Maloja district as a monthly total (Casdmt) | F1: campground overnight stays at short term spots in the Maloja district as a monthly total (Cosdmt) | G1: average number of overnight stays per arrival at short term camping spots in the Maloja district (Ctaoad) | H1: number of days in the month (Ndm) | I1: average number of tourist per night at short term camping spots in the Maloja district (Catnd) | J1: average number of arrivals and departures at short term camping spots in the Maloja district (Caadd)
A2: 45323 | B2: 4 | C2: =campgrounds!C26 -> 0 | D2: =$E$7*(C2/$B$7) -> 0 | E2: =(C2/$C$10)*$D$10 -> 0 | F2: =IF(C2>0, ((B13/$B$19)*$E$10), 0) -> 0 | G2: =F2/E2 -> #DIV/0! | H2: 29 | I2: =E2/(H2/(F2/E2)) -> #DIV/0! | J2: =(E2/H2)*2 -> 0
A3: 45505 | B3: 5 | C3: =campgrounds!C28 -> 579 | D3: =$E$7*(C3/$B$7) -> 3504 | E3: =(C3/$C$10)*$D$10 -> 6437.5745 | F3: =IF(C3>0, ((B14/$B$19)*$E$10), 0) -> 17992.695 | G3: =F3/E3 -> 2.7949495 | H3: 31 | I3: =E3/(H3/(F3/E3)) -> 580.40953 | J3: =(E3/H3)*2 -> 415.32739
A4: 45597 | B4: 3 | C4: =campgrounds!C30 -> 0 | D4: =$E$7*(C4/$B$7) -> 0 | E4: =(C4/$C$10)*$D$10 -> 0 | F4: =IF(C4>0, ((B15/$B$19)*$E$10), 0) -> 0 | G4: =F4/E4 -> #DIV/0! | H4: 30 | I4: =E4/(H4/(F4/E4)) -> #DIV/0! | J4: =(E4/H4)*2 -> 0
B6: camping spots short term in the Maloja district in total (Csdt) | C6: campground arrivals at short term spots in the canton of Grisons in total (Casct) | D6: campground overnight stays at short term spots in the canton of Grisons in total (Cosct) | E6: camping spots short term in the canton of Grisons in total (Csct)
B7: 579 | C7: 194795 | D7: 545143 | E7: 3504
B9: camping spots short term annual compound availability in the canton of Grisons (Csacc) | C9: camping spots short term annual compound availability in the Maloja district (Csacd) | D9: campground arrivals at short term spots in the Maloja district as an annual total (Casdt) | E9: campground arrivals at short term spots in the Maloja district as an annual total (Casdat)
B10: =D3*B3+D2*B2+D4*B4 -> 17520 | C10: =C3*B3+C2*B2+C4*B4 -> 2895 | D10: =C10*(C7/B10) -> 32187.872 | E10: =C10*(D7/B10) -> 90079.28
A12: month | B12: tourist overnight stays in hotels in the Maloja district per month customized curve (Htodmc)
A13: 45323 | B13: ='hotel overnightstay customcurve'!D36 -> 30547
A14: 45505 | B14: ='hotel overnightstay customcurve'!D42 -> 137039
A15: 45597 | B15: ='hotel overnightstay customcurve'!D45 -> 19650
B18: tourist overnight stays in hotels in the Maloja district per year customized curve (Htodyc)
B19: =SUM('hotel overnightstay customcurve'!D35:D46) -> 686077
A26: month | B26: campground | C26: camping spots | D26: share of camping spots in the study area | E26: average number of tourist per night at short term camping spots in the Maloja district (Catnd) | F26: average number of arrivals and departures at short term camping spots in the Maloja district (Caadd) | G26: average number of arrivals or departures at short term camping spots in the Maloja district
A27: 45505 | B27: Maloja | C27: 110 | D27: =C27/$C$3 -> 0.18998273 | E27: =D27*$I$3 -> 110.26779 | F27: =D27*$J$3 -> 78.90503 | G27: =F27/2 -> 39.452515
B28: Mulina | C28: 140 | D28: =C28/$C$3 -> 0.2417962 | E28: =D28*$I$3 -> 140.34082 | F28: =D28*$J$3 -> 100.42458 | G28: =F28/2 -> 50.212292
B29: Silvaplana | C29: 130 | D29: =C29/$C$3 -> 0.22452504 | E29: =D29*$I$3 -> 130.31647 | F29: =D29*$J$3 -> 93.251399 | G29: =F29/2 -> 46.6257
B30: St. Moritz | C30: 199 | D30: =C30/$C$3 -> 0.34369603 | E30: =D30*$I$3 -> 199.48445 | F30: =D30*$J$3 -> 142.74637 | G30: =F30/2 -> 71.373186
B32: PT usage rate | C32: grocery shopping on arrival rate
B33: 0.745 | C33: 0.4
A35: month | B35: campground | C35: average number of short term camping spot arrivals going grovery shopping by PT on arrival day | D35: average number of short term camping spot arrivals not going grovery shopping by PT on arrival day | E35: average number of short term camping spot tourists doing activities by PT | F35: tourists visiting sports areas in the summer season by public transportation | G35: tourists visiting other activities in the summer season by public transportation
A36: 45505 | B36: Maloja | C36: =G27*$B$33*$C$33 -> 11.756849 | D36: =G27*$B$33*(1-$C$33) -> 17.635274 | E36: =(E27-G27)*$B$33*2 -> 105.51475 | F36: =E36/2/7 -> 7.5367681 | G36: =E36/2/5 -> 10.551475
B37: Mulina | C37: =G28*$B$33*$C$33 -> 14.963263 | D37: =G28*$B$33*(1-$C$33) -> 22.444894 | E37: =(E28-G28)*$B$33*2 -> 134.2915 | F37: =E37/2/7 -> 9.5922503 | G37: =E37/2/5 -> 13.42915
B38: Silvaplana | C38: =G29*$B$33*$C$33 -> 13.894458 | D38: =G29*$B$33*(1-$C$33) -> 20.841688 | E38: =(E29-G29)*$B$33*2 -> 124.69925 | F38: =E38/2/7 -> 8.9070896 | G38: =E38/2/5 -> 12.469925
B39: St. Moritz | C39: =G30*$B$33*$C$33 -> 21.26921 | D39: =G30*$B$33*(1-$C$33) -> 31.903814 | E39: =(E30-G30)*$B$33*2 -> 190.88578 | F39: =E39/2/7 -> 13.634699 | G39: =E39/2/5 -> 19.088578
A41: month | B41: total PT demand
A42: 45323
A43: 45505 | B43: =(12+15+14+21)*2+((8+10+9+14)*7)*2+(11+12+13+12+19)*5 -> 1033
A44: 45597

Sheet campgrounds longterm alldata
A1: month | B1: camping spots long term in the Maloja district for the selected month (Cldm) | C1: estimated occupancy of long term camping spots (Cleo) | D1: estimated number of tourists that stay at long term camping spots in the Maloja district (Cletd)
A2: 45323 | B2: =campgrounds!D12 -> 152 | C2: 0.8 | D2: =B2*C2*2 -> 243.2
A3: 45505 | B3: =campgrounds!D14 -> 312 | C3: 0.8 | D3: =B3*C3*2 -> 499.2
A4: 45597 | B4: =campgrounds!D16 -> 142 | C4: 0.7 | D4: =B4*C4*2 -> 198.8

Sheet campgrounds longterm studyarea
A1: month | B1: camping spots long term in the Maloja district for the selected month (Cldm) | C1: estimated occupancy of long term camping spots (Cleo) | D1: estimated number of tourists that stay at long term camping spots in the Maloja district (Cletd)
A2: 45323 | B2: =campgrounds!D19 -> 142 | C2: 0.8 | D2: =B2*C2*2 -> 227.2
A3: 45505 | B3: =campgrounds!D21 -> 282 | C3: 0.8 | D3: =B3*C3*2 -> 451.2
A4: 45597 | B4: =campgrounds!D23 -> 142 | C4: 0.7 | D4: =B4*C4*2 -> 198.8

Sheet campgrounds longterm finalarea
A1: month | B1: camping spots long term in the Maloja district for the selected month (Cldm) | C1: estimated occupancy of long term camping spots (Cleo) | D1: estimated number of tourists that stay at long term camping spots in the Maloja district (Cletd)
A2: 45323 | B2: =campgrounds!D26 -> 0 | C2: 0.8 | D2: =B2*C2*2 -> 0
A3: 45505 | B3: =campgrounds!D28 -> 140 | C3: 0.8 | D3: =B3*C3*2 -> 224
A4: 45597 | B4: =campgrounds!D30 -> 0 | C4: 0.7 | D4: =B4*C4*2 -> 0
B6: PT usage rate | C6: grocery shopping rate
B7: 0.745 | C7: 0.2857
A10: month | B10: campground | C10: camping spots | D10: estimated number of tourists that stay at long term camping spots in the Maloja district | E10: non-grocery shopping trips per direction | F10: summer desinations | G10: general travel | H10: grocery shopping trips per direction
A11: 45505 | B11: Maloja | C11: 10 | D11: =C11*$C$3*2 -> 16 | E11: =D11*(2-$C$7)*$B$7 -> 20.434456 | F11: =E11/2/7 -> 1.459604 | G11: =E11/2/5 -> 2.0434456 | H11: =D11*$C$7*$B$7 -> 3.405544
B12: Mulina | C12: 10 | D12: =C12*$C$3*2 -> 16 | E12: =D12*(2-$C$7)*$B$7 -> 20.434456 | F12: =E12/2/7 -> 1.459604 | G12: =E12/2/5 -> 2.0434456 | H12: =D12*$C$7*$B$7 -> 3.405544
B13: Silvaplana | C13: 120 | D13: =C13*$C$3*2 -> 192 | E13: =D13*(2-$C$7)*$B$7 -> 245.21347 | F13: =E13/2/7 -> 17.515248 | G13: =E13/2/5 -> 24.521347 | H13: =D13*$C$7*$B$7 -> 40.866528
B14: St. Moritz | C14: 0 | D14: =C14*$C$3*2 -> 0 | E14: =D14*(2-$C$7)*$B$7 -> 0 | F14: =E14/2/7 -> 0 | G14: =E14/2/5 -> 0 | H14: =D14*$C$7*$B$7 -> 0
A16: month | B16: total PT demand
A17: 45323
A18: 45505 | B18: =(3+3+41+0)*2+((2+2+25+0)*7)*2+(1+1+1+18+0)*5 -> 605
A19: 45597

Sheet daytrip tourists alldata
A1: month | B1: tourist overnight stays in hotels in the Maloja district per month (Htodm) | C1: tourist overnight stays in non hotels in the Maloja district per month (Ntodm) | D1: campground overnight stays at short term spots in the Maloja district as a monthly total (Cosdmt) | E1: campground overnight stays at long term camping spots in the Maloja district as a monthly total | F1: total number of tourist that stay overnight in the Maloja district per month (Tod) | G1: day trip tourist factor as a percentage of the total number of tourists in the Maloja district (Dtptd) | H1: total number of day trip tourist in the Maloja district per month (Dtdm) | I1: average number of day trip tourist in the Maloja district per day (Dtdd)
A2: 45323 | B2: ='hotel alldata'!C2 -> 254496 | C2: ='non-hotel alldata'!C2 -> 131219.28 | D2: ='campgrounds shortterm alldata'!F2 -> 6808.4629 | E2: ='campgrounds longterm alldata'!D2*29 -> 7052.8 | F2: =B2*2+C2+D2+E2 -> 654072.55 | G2: 0.2 | H2: =F2*((1/(1-G2))-1) -> 163518.14 | I2: =H2/29 -> 5638.5564
A3: 45505 | B3: ='hotel alldata'!C3 -> 209937 | C3: ='non-hotel alldata'!C3 -> 108244.46 | D3: ='campgrounds shortterm alldata'!F3 -> 32916.848 | E3: ='campgrounds longterm alldata'!D3*31 -> 15475.2 | F3: =B3*2+C3+D3+E3 -> 576510.51 | G3: 0.17 | H3: =F3*((1/(1-G3))-1) -> 118080.47 | I3: =H3/31 -> 3809.0473
A4: 45597 | B4: ='hotel alldata'!C4 -> 36859 | C4: ='non-hotel alldata'!C4 -> 19004.666 | D4: ='campgrounds shortterm alldata'!F4 -> 5779.2675 | E4: ='campgrounds longterm alldata'!D4*30 -> 5964 | F4: =B4*2+C4+D4+E4 -> 104465.93 | G4: 0.2 | H4: =F4*((1/(1-G4))-1) -> 26116.483 | I4: =H4/30 -> 870.54945

Sheet daytrip tourists studyarea
A1: month | B1: tourist overnight stays in hotels in the Maloja district per month (Htodm) | C1: tourist overnight stays in non hotels in the Maloja district per month (Ntodm) | D1: campground overnight stays at short term spots in the Maloja district as a monthly total (Cosdmt) | E1: campground overnight stays at long term camping spots in the Maloja district as a monthly total | F1: total number of tourist that stay overnight in the Maloja district per month (Tod) | G1: day trip tourist factor as a percentage of the total number of tourists in the Maloja district (Dtptd) | H1: total number of day trip tourist in the Maloja district per month (Dtdm) | I1: average number of day trip tourist in the Maloja district per day (Dtdd)
A2: 45323 | B2: ='hotel studyarea'!C2 -> 248763 | C2: ='non-hotel studyarea'!C2 -> 128263.32 | D2: ='campgrounds shortterm studyarea'!F2 -> 5984.7168 | E2: ='campgrounds longterm studyarea'!D2*29 -> 6588.8 | F2: =B2*2+C2+D2+E2 -> 638362.84 | G2: 0.2 | H2: =F2*((1/(1-G2))-1) -> 159590.71 | I2: =H2/29 -> 5503.1279
A3: 45505 | B3: ='hotel studyarea'!C3 -> 206231 | C3: ='non-hotel studyarea'!C3 -> 106333.63 | D3: ='campgrounds shortterm studyarea'!F3 -> 28854.775 | E3: ='campgrounds longterm studyarea'!D3*31 -> 13987.2 | F3: =B3*2+C3+D3+E3 -> 561637.61 | G3: 0.17 | H3: =F3*((1/(1-G3))-1) -> 115034.21 | I3: =H3/31 -> 3710.7809
A4: 45597 | B4: ='hotel studyarea'!C4 -> 36085 | C4: ='non-hotel studyarea'!C4 -> 18605.589 | D4: ='campgrounds shortterm studyarea'!F4 -> 5048.8266 | E4: ='campgrounds longterm studyarea'!D4*30 -> 5964 | F4: =B4*2+C4+D4+E4 -> 101788.42 | G4: 0.2 | H4: =F4*((1/(1-G4))-1) -> 25447.104 | I4: =H4/30 -> 848.23679

Sheet daytrip tourists finalarea
A1: month | B1: tourist overnight stays in hotels in the Maloja district per month (Htodm) | C1: tourist overnight stays in non hotels in the Maloja district per month (Ntodm) | D1: campground overnight stays at short term camping spots in the Maloja district as a monthly total (Cosdmt) | E1: campground overnight stays at long term camping spots in the Maloja district as a monthly total | F1: total number of tourist that stay overnight in the Maloja district per month (Tod) | G1: day trip tourist factor as a percentage of the total number of tourists in the Maloja district (Dtptd) | H1: total number of day trip tourist in the Maloja district per month (Dtdm) | I1: average number of day trip tourist in the Maloja district per day (Dtdd)
A2: 45323 | B2: ='hotel finalarea'!C2 -> 165513 | C2: ='non-hotel finalarea'!C2 -> 85339.248 | D2: ='campgrounds shortterm finalarea'!F2 -> 0 | E2: ='campgrounds longterm finalarea'!D2*29 -> 0 | F2: =B2*2+C2+D2+E2 -> 416365.25 | G2: 0.2 | H2: =F2*((1/(1-G2))-1) -> 104091.31 | I2: =H2/29 -> 3589.3556
A3: 45505 | B3: ='hotel finalarea'!C3 -> 137039 | C3: ='non-hotel finalarea'!C3 -> 70657.926 | D3: ='campgrounds shortterm finalarea'!F3 -> 17992.695 | E3: ='campgrounds longterm finalarea'!D3*31 -> 6944 | F3: =B3*2+C3+D3+E3 -> 369672.62 | G3: 0.17 | H3: =F3*((1/(1-G3))-1) -> 75716.079 | I3: =H3/31 -> 2442.4542
A4: 45597 | B4: ='hotel finalarea'!C4 -> 19650 | C4: ='non-hotel finalarea'!C4 -> 10131.628 | D4: ='campgrounds shortterm finalarea'!F4 -> 0 | E4: ='campgrounds longterm finalarea'!D4*30 -> 0 | F4: =B4*2+C4+D4+E4 -> 49431.628 | G4: 0.2 | H4: =F4*((1/(1-G4))-1) -> 12357.907 | I4: =H4/30 -> 411.93024
B6: arrival by public transportation rate | C6: tourists visiting winter sports areas rate | D6: winter season other activities rate | E6: tourists visiting summer sports areas rate | F6: summer season other activities rate | G6: tourists visiting off season sports areas rate | H6: off season other activities rate
B7: 0.35 | C7: 0.7 | D7: 0.3 | E7: 0.5 | F7: 0.5 | G7: 0.3 | H7: 0.7
A8: month | B8: tourists arriving/departing by public transportation | C8: tourists visiting sports areas in the winter season by public transportation | D8: tourists visiting other activities in the winter season by public transportation | E8: tourists visiting sports areas in the summer season by public transportation | F8: tourists visiting other activities in the summer season by public transportation | G8: tourists visiting sports areas in the off season by public transportation | H8: tourists visiting other activities in the off season by public transportation | I8: additional trips
A9: 45323 | B9: =I2*B$7 -> 1256.2745 | C9: =($I2*$B$7*C$7)/2 -> 439.69606 | D9: =($I2*$B$7*D$7)/4 -> 94.220584 | I9: 20
A10: 45505 | B10: =I3*B$7 -> 854.85896 | E10: =($I3*$B$7*E$7)/7 -> 61.061354 | F10: =($I3*$B$7*F$7)/4 -> 106.85737 | I10: 16
A11: 45597 | B11: =I4*B$7 -> 144.17558 | G11: =($I4*$B$7*G$7)/4 -> 10.813169 | H11: =($I4*$B$7*H$7)/4 -> 25.230727 | I11: 8
A13: month | B13: total PT demand
A14: 45323 | B14: =(440*2)*2+(94*4)*2+20*16 -> 2832
A15: 45505 | B15: =(61*7)*2+(107*4)*2+16*16 -> 1966
A16: 45597 | B16: =(11*4)*2+(25*4)*2+(8*16) -> 416

Sheet total tourists alldata
A1: month | B1: tourist overnight stays in hotels in the Maloja district per month (Htodm) | C1: tourist overnight stays in non hotels in the Maloja district per month (Ntodm) | D1: campground overnight stays at short term spots in the Maloja district as a monthly total (Cosdmt) | E1: estimated number of tourists that stay at long term camping spots in the Maloja district (Cletd) | F1: total number of day trip tourist in the Maloja district per month (Dtdm) | G1: total number of tourists in the Maloja district per month (Ttdm) | H1: total number of tourists in the Maloja district per day (Ttdd)
A2: 45323 | B2: ='hotel alldata'!C2 -> 254496 | C2: ='non-hotel alldata'!C2 -> 131219.28 | D2: ='campgrounds shortterm alldata'!F2 -> 6808.4629 | E2: ='campgrounds longterm alldata'!D2 -> 243.2 | F2: ='daytrip tourists alldata'!H2 -> 163518.14 | G2: =B2*2+C2+D2+E2+F2 -> 810781.08 | H2: =G2/29 -> 27957.968
A3: 45505 | B3: ='hotel alldata'!C3 -> 209937 | C3: ='non-hotel alldata'!C3 -> 108244.46 | D3: ='campgrounds shortterm alldata'!F3 -> 32916.848 | E3: ='campgrounds longterm alldata'!D3 -> 499.2 | F3: ='daytrip tourists alldata'!I3 -> 3809.0473 | G3: =B3*2+C3+D3+E3+F3 -> 565343.56 | H3: =G3/31 -> 18236.889
A4: 45597 | B4: ='hotel alldata'!C4 -> 36859 | C4: ='non-hotel alldata'!C4 -> 19004.666 | D4: ='campgrounds shortterm alldata'!F4 -> 5779.2675 | E4: ='campgrounds longterm alldata'!D4 -> 198.8 | F4: ='daytrip tourists alldata'!I4 -> 870.54945 | G4: =B4*2+C4+D4+E4+F4 -> 99571.283 | H4: =G4/30 -> 3319.0428

Sheet total tourists studyarea
A1: month | B1: tourist overnight stays in hotels in the Maloja district per month (Htodm) | C1: tourist overnight stays in non hotels in the Maloja district per month (Ntodm) | D1: campground overnight stays at short term spots in the Maloja district as a monthly total (Cosdmt) | E1: estimated number of tourists that stay at long term camping spots in the Maloja district (Cletd) | F1: total number of day trip tourist in the Maloja district per month (Dtdm) | G1: total number of tourists in the Maloja district per month (Ttdm) | H1: total number of tourists in the Maloja district per day (Ttdd)
A2: 45323 | B2: ='hotel studyarea'!C2 -> 248763 | C2: ='non-hotel studyarea'!C2 -> 128263.32 | D2: ='campgrounds shortterm studyarea'!F2 -> 5984.7168 | E2: ='campgrounds longterm studyarea'!D2 -> 227.2 | F2: ='daytrip tourists studyarea'!H2 -> 159590.71 | G2: =B2*2+C2+D2+E2+F2 -> 791591.95 | H2: =G2/29 -> 27296.274
A3: 45505 | B3: ='hotel studyarea'!C3 -> 206231 | C3: ='non-hotel studyarea'!C3 -> 106333.63 | D3: ='campgrounds shortterm studyarea'!F3 -> 28854.775 | E3: ='campgrounds longterm studyarea'!D3 -> 451.2 | F3: ='daytrip tourists studyarea'!H3 -> 115034.21 | G3: =B3*2+C3+D3+E3+F3 -> 663135.82 | H3: =G3/31 -> 21391.478
A4: 45597 | B4: ='hotel studyarea'!C4 -> 36085 | C4: ='non-hotel studyarea'!C4 -> 18605.589 | D4: ='campgrounds shortterm studyarea'!F4 -> 5048.8266 | E4: ='campgrounds longterm studyarea'!D4 -> 198.8 | F4: ='daytrip tourists studyarea'!H4 -> 25447.104 | G4: =B4*2+C4+D4+E4+F4 -> 121470.32 | H4: =G4/30 -> 4049.0106

Sheet total tourists finalarea
A1: month | B1: tourist overnight stays in hotels in the Maloja district per month (Htodm) | C1: tourist overnight stays in private accommodation in the Maloja district per month | D1: tourist overnight stays in non hotels in the Maloja district per month (Ntodm) | E1: campground overnight stays at short term spots in the Maloja district as a monthly total (Cosdmt) | F1: estimated number of tourists that stay at long term camping spots in the Maloja district (Cletd) | G1: total number of day trip tourist in the Maloja district per month (Dtdm) | H1: total number of tourists in the Maloja district per month (Ttdm) | I1: total number of tourists in the Maloja district per day (Ttdd)
A2: 45323 | B2: ='hotel finalarea'!C2 -> 165513 | C2: =B2 -> 165513 | D2: ='non-hotel finalarea'!C2 -> 85339.248 | E2: ='campgrounds shortterm finalarea'!F2 -> 0 | F2: ='campgrounds longterm finalarea'!D2 -> 0 | G2: ='daytrip tourists finalarea'!H2 -> 104091.31 | H2: =B2+C2+D2+E2+F2+G2 -> 520456.56 | I2: =H2/29 -> 17946.778
A3: 45505 | B3: ='hotel finalarea'!C3 -> 137039 | C3: =B3 -> 137039 | D3: ='non-hotel finalarea'!C3 -> 70657.926 | E3: ='campgrounds shortterm finalarea'!F3 -> 17992.695 | F3: ='campgrounds longterm finalarea'!D3 -> 224 | G3: ='daytrip tourists finalarea'!H3 -> 75716.079 | H3: =B3+C3+D3+E3+F3+G3 -> 438668.7 | I3: =H3/31 -> 14150.603
A4: 45597 | B4: ='hotel finalarea'!C4 -> 19650 | C4: =B4 -> 19650 | D4: ='non-hotel finalarea'!C4 -> 10131.628 | E4: ='campgrounds shortterm finalarea'!F4 -> 0 | F4: ='campgrounds longterm finalarea'!D4 -> 0 | G4: ='daytrip tourists finalarea'!H4 -> 12357.907 | H4: =B4+C4+D4+E4+F4+G4 -> 61789.536 | I4: =H4/30 -> 2059.6512
A6: month | B6: arrival/departure by public transportation rate
B7: 0.3 | C7: 0.3 | D7: 0.3 | E7: 0 | F7: 0 | G7: 0.3
A8: 45323 | B8: ='hotel finalarea'!G2*B$7 -> 885.04138 | C8: ='hotel finalarea'!G2*C$7 -> 885.04138 | D8: ='non-hotel finalarea'!F2*D$7 -> 253.47595 | E8: ='campgrounds shortterm finalarea'!J2*E$7 -> 0 | F8: 0 | G8: =G2/29*G$7 -> 1076.8067
A9: 45505 | B9: ='hotel finalarea'!G3*B$7 -> 963.44516 | C9: ='hotel finalarea'!G3*C$7 -> 963.44516 | D9: ='non-hotel finalarea'!F3*D$7 -> 275.9308 | E9: ='campgrounds shortterm finalarea'!J3*E$7 -> 0 | F9: 0 | G9: =G3/31*G$7 -> 732.73625
A10: 45597 | B10: ='hotel finalarea'!G4*B$7 -> 205.48 | C10: ='hotel finalarea'!G4*C$7 -> 205.48 | D10: ='non-hotel finalarea'!F4*D$7 -> 58.849495 | E10: ='campgrounds shortterm finalarea'!J4*E$7 -> 0 | F10: 0 | G10: =G4/30*G$7 -> 123.57907
A12: month | B12: going arround the destination by public transportation rate
B13: 0.5 | C13: 0.5 | D13: 0.5 | E13: 0.745 | F13: 0.745 | G13: 0.3
A14: 45323 | B14: ='hotel finalarea'!F2*B$13 -> 2853.6724 | C14: ='hotel finalarea'!F2*C$13 -> 2853.6724 | D14: ='non-hotel finalarea'!E2*D$13 -> 1471.3663 | E14: ='campgrounds shortterm finalarea'!I2*E$13 -> #DIV/0! | F14: ='campgrounds longterm finalarea'!D2*F$13 -> 0 | G14: ='daytrip tourists finalarea'!I2*G$13 -> 1076.8067
A15: 45505 | B15: ='hotel finalarea'!F3*B$13 -> 2210.3065 | C15: ='hotel finalarea'!F3*C$13 -> 2210.3065 | D15: ='non-hotel finalarea'!E3*D$13 -> 1139.644 | E15: ='campgrounds shortterm finalarea'!I3*E$13 -> 432.4051 | F15: ='campgrounds longterm finalarea'!D3*F$13 -> 166.88 | G15: ='daytrip tourists finalarea'!I3*G$13 -> 732.73625
A16: 45597 | B16: ='hotel finalarea'!F4*B$13 -> 327.5 | C16: ='hotel finalarea'!F4*C$13 -> 327.5 | D16: ='non-hotel finalarea'!E4*D$13 -> 168.86047 | E16: ='campgrounds shortterm finalarea'!I4*E$13 -> #DIV/0! | F16: ='campgrounds longterm finalarea'!D4*F$13 -> 0 | G16: ='daytrip tourists finalarea'!I4*G$13 -> 123.57907
A18: month | B18: going grocery shopping the destination by public transportation rate
B19: 0.5 | C19: 0.5 | D19: 0.5 | E19: 0.745 | F19: 0.745 | G19: 0.3
B20: grocery shopping only trips
B21: 0 | C21: 0.4 | D21: 0.4 | E21: 0.4 | F21: 0.2857 | G21: 0
A22: 45323 | B22: 0 | C22: ='hotel finalarea'!G2*C$21*C$19 -> 590.02759 | D22: ='non-hotel finalarea'!F2*D$21*D$19 -> 168.98397 | E22: ='non-hotel finalarea'!F2*E$21*E$19 -> 251.78611 | F22: ='campgrounds longterm finalarea'!D2*F$21*F$19 -> 0 | G22: 0
A23: 45505 | B23: 0 | C23: ='hotel finalarea'!G3*C$21*C$19 -> 642.29677 | D23: ='non-hotel finalarea'!F3*D$21*D$19 -> 183.95387 | E23: ='non-hotel finalarea'!F3*E$21*E$19 -> 274.09126 | F23: ='campgrounds longterm finalarea'!D3*F$21*F$19 -> 47.677616 | G23: 0
A24: 45597 | B24: 0 | C24: ='hotel finalarea'!G4*C$21*C$19 -> 136.98667 | D24: ='non-hotel finalarea'!F4*D$21*D$19 -> 39.232997 | E24: ='non-hotel finalarea'!F4*E$21*E$19 -> 58.457165 | F24: ='campgrounds longterm finalarea'!D4*F$21*F$19 -> 0 | G24: 0
A26: month | B26: total PT demand
A27: 45323 | B27: ='hotel finalarea'!B38+'non-hotel finalarea'!B34+'campgrounds shortterm finalarea'!B42+'campgrounds longterm finalarea'!B17+'daytrip tourists finalarea'!B14+'tourists private acco PT'!D32 -> 8378
A28: 45505 | B28: ='hotel finalarea'!B39+'non-hotel finalarea'!B35+'campgrounds shortterm finalarea'!B43+'campgrounds longterm finalarea'!B18+'daytrip tourists finalarea'!B15+'tourists private acco PT'!D33 -> 9436
A29: 45597 | B29: ='hotel finalarea'!B40+'non-hotel finalarea'!B36+'campgrounds shortterm finalarea'!B44+'campgrounds longterm finalarea'!B19+'daytrip tourists finalarea'!B16+'tourists private acco PT'!D34 -> 1492
B31: total annual PT demand
B32: =B29*(30*3)+B28*(30*5+3)+B27*(30*4+2) -> 2600104

Sheet tourists private acco PT
A1: municipality | B1: month | C1: tourist arrivals in private accomodation | D1: tourist overnight stays in private accomodation | E1: tourist average number of overnight stays per arrival in private accommodation | F1: average number of tourist per night in private accommodation | G1: average number of arrivals and departures in private accommodation | H1: average number of arrivals or departures in private accommodation
A2: Sils im Engadin/Segl | B2: 45323 | C2: 7607 | D2: 33359 | E2: =D2/C2 -> 4.385303 | F2: =C2/(29/E2) -> 1150.3103 | G2: =(C2/29)*2 -> 524.62069 | H2: =G2/2 -> 262.31034
B3: 45505 | C3: 7347 | D3: 28885 | E3: =D3/C3 -> 3.9315367 | F3: =C3/(31/E3) -> 931.77419 | G3: =(C3/31)*2 -> 474 | H3: =G3/2 -> 237
B4: 45597 | C4: 455 | D4: 906 | E4: =D4/C4 -> 1.9912088 | F4: =C4/(30/E4) -> 30.2 | G4: =(C4/30)*2 -> 30.333333 | H4: =G4/2 -> 15.166667
A5: Silvaplana | B5: 45323 | C5: 3610 | D5: 13348 | E5: =D5/C5 -> 3.6975069 | F5: =C5/(29/E5) -> 460.27586 | G5: =(C5/29)*2 -> 248.96552 | H5: =G5/2 -> 124.48276
B6: 45505 | C6: 3403 | D6: 10514 | E6: =D6/C6 -> 3.0896268 | F6: =C6/(31/E6) -> 339.16129 | G6: =(C6/31)*2 -> 219.54839 | H6: =G6/2 -> 109.77419
B7: 45597 | C7: 945 | D7: 2224 | E7: =D7/C7 -> 2.3534392 | F7: =C7/(30/E7) -> 74.133333 | G7: =(C7/30)*2 -> 63 | H7: =G7/2 -> 31.5
A8: Bregaglia | B8: 45323 | C8: 2225 | D8: 6692 | E8: =D8/C8 -> 3.0076404 | F8: =C8/(29/E8) -> 230.75862 | G8: =(C8/29)*2 -> 153.44828 | H8: =G8/2 -> 76.724138
B9: 45505 | C9: 4315 | D9: 10753 | E9: =D9/C9 -> 2.4920046 | F9: =C9/(31/E9) -> 346.87097 | G9: =(C9/31)*2 -> 278.3871 | H9: =G9/2 -> 139.19355
B10: 45597 | C10: 193 | D10: 427 | E10: =D10/C10 -> 2.2124352 | F10: =C10/(30/E10) -> 14.233333 | G10: =(C10/30)*2 -> 12.866667 | H10: =G10/2 -> 6.4333333
A11: St. Moritz | B11: 45323 | C11: 29335 | D11: 112114 | E11: =D11/C11 -> 3.821851 | F11: =C11/(29/E11) -> 3866 | G11: =(C11/29)*2 -> 2023.1034 | H11: =G11/2 -> 1011.5517
B12: 45505 | C12: 34713 | D12: 86887 | E12: =D12/C12 -> 2.5030104 | F12: =C12/(31/E12) -> 2802.8065 | G12: =(C12/31)*2 -> 2239.5484 | H12: =G12/2 -> 1119.7742
B13: 45597 | C13: 8681 | D13: 16093 | E13: =D13/C13 -> 1.8538187 | F13: =C13/(30/E13) -> 536.43333 | G13: =(C13/30)*2 -> 578.73333 | H13: =G13/2 -> 289.36667
A15: tourists getting around by public transportation rate | C15: arrival/departure by public transportation rate | D15: grocery shopping rate | E15: tourists visiting winter sports areas rate | F15: winter season other activities rate | G15: tourists visiting summer sports areas rate | H15: summer season other activities rate | I15: tourists visiting off season sports areas rate | J15: off season other activities rate
A16: 0.15 | C16: 0.3 | D16: 0.1 | E16: 0.7 | F16: 0.3 | G16: 0.5 | H16: 0.5 | I16: 0.3 | J16: 0.7
A17: municipality | B17: month | C17: tourists arriving/departing by public transportation | D17: tourists going grocery shopping by public transportation | E17: tourists visiting winter sports areas by public transportation | F17: tourists visiting other activities in the winter season by public transportation | G17: tourists visiting sports areas in the summer season by public transportation | H17: tourists visiting other activities in the summer season by public transportation | I17: tourists visiting sports areas in the off season by public transportation | J17: tourists visiting other activities in the off season by public transportation
A18: Sils im Engadin/Segl | B18: 45323 | C18: =H2*C$16 -> 78.693103 | D18: =H2*$A$16*$D$16 -> 3.9346552 | E18: =((F2*2)*$E$16*$A$16)/2 -> 120.78259 | F18: =((F2*2)*$F$16*$A$16)/2/5 -> 10.352793
